Workbook

Sheet Sistema de Ecuaciones
A1: Sistema de Ecuaciones
A2: a | B2: b | C2: c | D2: d | E2: e | F2: f | G2: Igualdad
A3: 2 | B3: -3 | C3: 0 | D3: 0 | E3: 0 | F3: 0 | G3: =-5/3 -> -1.6666667
A4: -1 | B4: 4 | C4: -1 | D4: 0 | E4: -1 | F4: 0 | G4: 0.66666667
A5: 0 | B5: -1 | C5: 4 | D5: 0 | E5: 0 | F5: -1 | G5: 3
A6: 0 | B6: 0 | C6: 0 | D6: 2 | E6: -3 | F6: 0 | G6: =-4/3 -> -1.3333333
A7: 0 | B7: -1 | C7: 0 | D7: -1 | E7: 4 | F7: -1 | G7: =-1/3 -> -0.33333333
A8: 0 | B8: 0 | C8: -1 | D8: 0 | E8: -1 | F8: 4 | G8: 1.6666667
A10: Estudiantes | B10: Jonás Samuel Salazar Torres
B11: Alexander Yama Rosero
B12: Daniel Alejandro Trujillo Figueroa

Sheet Eliminación de Gauss
A2: a | B2: b | C2: c | D2: d | E2: e | F2: f | G2: Igualdad
A3: ='Sistema de Ecuaciones'!A3 -> 2 | B3: ='Sistema de Ecuaciones'!B3 -> -3 | C3: ='Sistema de Ecuaciones'!C3 -> 0 | D3: ='Sistema de Ecuaciones'!D3 -> 0 | E3: ='Sistema de Ecuaciones'!E3 -> 0 | F3: ='Sistema de Ecuaciones'!F3 -> 0 | G3: ='Sistema de Ecuaciones'!G3 -> -1.6666667
A4: ='Sistema de Ecuaciones'!A4 -> -1 | B4: ='Sistema de Ecuaciones'!B4 -> 4 | C4: ='Sistema de Ecuaciones'!C4 -> -1 | D4: ='Sistema de Ecuaciones'!D4 -> 0 | E4: ='Sistema de Ecuaciones'!E4 -> -1 | F4: ='Sistema de Ecuaciones'!F4 -> 0 | G4: ='Sistema de Ecuaciones'!G4 -> 0.66666667
A5: ='Sistema de Ecuaciones'!A5 -> 0 | B5: ='Sistema de Ecuaciones'!B5 -> -1 | C5: ='Sistema de Ecuaciones'!C5 -> 4 | D5: ='Sistema de Ecuaciones'!D5 -> 0 | E5: ='Sistema de Ecuaciones'!E5 -> 0 | F5: ='Sistema de Ecuaciones'!F5 -> -1 | G5: ='Sistema de Ecuaciones'!G5 -> 3
A6: ='Sistema de Ecuaciones'!A6 -> 0 | B6: ='Sistema de Ecuaciones'!B6 -> 0 | C6: ='Sistema de Ecuaciones'!C6 -> 0 | D6: ='Sistema de Ecuaciones'!D6 -> 2 | E6: ='Sistema de Ecuaciones'!E6 -> -3 | F6: ='Sistema de Ecuaciones'!F6 -> 0 | G6: ='Sistema de Ecuaciones'!G6 -> -1.3333333
A7: ='Sistema de Ecuaciones'!A7 -> 0 | B7: ='Sistema de Ecuaciones'!B7 -> -1 | C7: ='Sistema de Ecuaciones'!C7 -> 0 | D7: ='Sistema de Ecuaciones'!D7 -> -1 | E7: ='Sistema de Ecuaciones'!E7 -> 4 | F7: ='Sistema de Ecuaciones'!F7 -> -1 | G7: ='Sistema de Ecuaciones'!G7 -> -0.33333333
A8: ='Sistema de Ecuaciones'!A8 -> 0 | B8: ='Sistema de Ecuaciones'!B8 -> 0 | C8: ='Sistema de Ecuaciones'!C8 -> -1 | D8: ='Sistema de Ecuaciones'!D8 -> 0 | E8: ='Sistema de Ecuaciones'!E8 -> -1 | F8: ='Sistema de Ecuaciones'!F8 -> 4 | G8: ='Sistema de Ecuaciones'!G8 -> 1.6666667
A10: a | B10: b | C10: c | D10: d | E10: e | F10: f | G10: Igualdad | I10: a | J10: b | K10: c | L10: d | M10: e | N10: f | O10: Igualdad
A11: =IF($A$3=1,A3,A3/$A$3) -> 1 | B11: =IF($A$3=1,B3,B3/$A$3) -> -1.5 | C11: =IF($A$3=1,C3,C3/$A$3) -> 0 | D11: =IF($A$3=1,D3,D3/$A$3) -> 0 | E11: =IF($A$3=1,E3,E3/$A$3) -> 0 | F11: =IF($A$3=1,F3,F3/$A$3) -> 0 | G11: =IF($A$3=1,G3,G3/$A$3) -> -0.83333333 | I11: =A27 -> 1 | J11: =B27 -> -1.5 | K11: =C27 -> 0 | L11: =D27 -> 0 | M11: =E27 -> 0 | N11: =F27 -> 0 | O11: =G27 -> -0.83333333
A12: =IF($A$4<0,A11*-$A$4+A4,IF($A$4>0,A11*-$A$4+A4,IF($A$4=0,A4))) -> 0 | B12: =IF($A$4<0,B11*-$A$4+B4,IF($A$4>0,B11*-$A$4+B4,IF($A$4=0,C4))) -> 2.5 | C12: =IF($A$4<0,C11*-$A$4+C4,IF($A$4>0,C11*-$A$4+C4,IF($A$4=0,D4))) -> -1 | D12: =IF($A$4<0,D11*-$A$4+D4,IF($A$4>0,D11*-$A$4+D4,IF($A$4=0,E4))) -> 0 | E12: =IF($A$4<0,E11*-$A$4+E4,IF($A$4>0,E11*-$A$4+E4,IF($A$4=0,F4))) -> -1 | F12: =IF($A$4<0,F11*-$A$4+F4,IF($A$4>0,F11*-$A$4+F4,IF($A$4=0,G4))) -> 0 | G12: =IF($A$4<0,G11*-$A$4+G4,IF($A$4>0,G11*-$A$4+G4,IF($A$4=0,H4))) -> -0.16666667 | I12: =A28 -> 0 | J12: =B28 -> 1 | K12: =C28 -> -0.4 | L12: =D28 -> 0 | M12: =E28 -> -0.4 | N12: =F28 -> 0 | O12: =G28 -> -0.066666667
A13: =IF($A$5<0,A11*-$A$5+A5,IF($A$5>0,A11*-$A$5+A5,IF($A$5=0,A5))) -> 0 | B13: =IF($A$5<0,B11*-$A$5+B5,IF($A$5>0,B11*-$A$5+B5,IF($A$5=0,B5))) -> -1 | C13: =IF($A$5<0,C11*-$A$5+C5,IF($A$5>0,C11*-$A$5+C5,IF($A$5=0,C5))) -> 4 | D13: =IF($A$5<0,D11*-$A$5+D5,IF($A$5>0,D11*-$A$5+D5,IF($A$5=0,D5))) -> 0 | E13: =IF($A$5<0,E11*-$A$5+E5,IF($A$5>0,E11*-$A$5+E5,IF($A$5=0,E5))) -> 0 | F13: =IF($A$5<0,F11*-$A$5+F5,IF($A$5>0,F11*-$A$5+F5,IF($A$5=0,F5))) -> -1 | G13: =IF($A$5<0,G11*-$A$5+G5,IF($A$5>0,G11*-$A$5+G5,IF($A$5=0,G5))) -> 3 | I13: =A29 -> 0 | J13: =B29 -> 0 | K13: =C29 -> 1 | L13: =D29 -> 0 | M13: =E29 -> -0.11111111 | N13: =F29 -> -0.27777778 | O13: =G29 -> 0.81481481
A14: =IF($A$6<0,A11*-$A$6+A6,IF($A$6>0,A11*-$A$6+A6,IF($A$6=0,A6))) -> 0 | B14: =IF($A$6<0,B11*-$A$6+B6,IF($A$6>0,B11*-$A$6+B6,IF($A$6=0,B6))) -> 0 | C14: =IF($A$6<0,C11*-$A$6+C6,IF($A$6>0,C11*-$A$6+C6,IF($A$6=0,C6))) -> 0 | D14: =IF($A$6<0,D11*-$A$6+D6,IF($A$6>0,D11*-$A$6+D6,IF($A$6=0,D6))) -> 2 | E14: =IF($A$6<0,E11*-$A$6+E6,IF($A$6>0,E11*-$A$6+E6,IF($A$6=0,E6))) -> -3 | F14: =IF($A$6<0,F11*-$A$6+F6,IF($A$6>0,F11*-$A$6+F6,IF($A$6=0,F6))) -> 0 | G14: =IF($A$6<0,G11*-$A$6+G6,IF($A$6>0,G11*-$A$6+G6,IF($A$6=0,G6))) -> -1.3333333 | I14: =A30 -> 0 | J14: =B30 -> 0 | K14: =C30 -> 0 | L14: =IF($D$30=1,D30,D30/$D$30) -> 1 | M14: =IF($D$30=1,E30,E30/$D$30) -> -1.5 | N14: =IF($D$30=1,F30,F30/$D$30) -> 0 | O14: =IF($D$30=1,G30,G30/$D$30) -> -0.66666667
A15: =IF($A$7<0,A11*-$A$7+A7,IF($A$7>0,A11*-$A$7+A7,IF($A$7=0,A7))) -> 0 | B15: =IF($A$7<0,B11*-$A$7+B7,IF($A$7>0,B11*-$A$7+B7,IF($A$7=0,B7))) -> -1 | C15: =IF($A$7<0,C11*-$A$7+C7,IF($A$7>0,C11*-$A$7+C7,IF($A$7=0,C7))) -> 0 | D15: =IF($A$7<0,D11*-$A$7+D7,IF($A$7>0,D11*-$A$7+D7,IF($A$7=0,D7))) -> -1 | E15: =IF($A$7<0,E11*-$A$7+E7,IF($A$7>0,E11*-$A$7+E7,IF($A$7=0,E7))) -> 4 | F15: =IF($A$7<0,F11*-$A$7+F7,IF($A$7>0,F11*-$A$7+F7,IF($A$7=0,F7))) -> -1 | G15: =IF($A$7<0,G11*-$A$7+G7,IF($A$7>0,G11*-$A$7+G7,IF($A$7=0,G7))) -> -0.33333333 | I15: =A31 -> 0 | J15: =B31 -> 0 | K15: =C31 -> 0 | L15: =IF($D$31<0,L14*-$D$31+D31,IF($D$31>0,L14*-$D$31+D31,IF($D$31=0,D31))) -> 0 | M15: =IF($D$31<0,M14*-$D$31+E31,IF($D$31>0,M14*-$D$31+E31,IF($D$31=0,E31))) -> 2.0555556 | N15: =IF($D$31<0,N14*-$D$31+F31,IF($D$31>0,N14*-$D$31+F31,IF($D$31=0,F31))) -> -1.1111111 | O15: =IF($D$31<0,O14*-$D$31+G31,IF($D$31>0,O14*-$D$31+G31,IF($D$31=0,G31))) -> -0.74074074
A16: =IF($A$8<0,A11*-$A$8+A8,IF($A$8>0,A11*-$A$8+A8,IF($A$8=0,A8))) -> 0 | B16: =IF($A$8<0,B11*-$A$8+B8,IF($A$8>0,B11*-$A$8+B8,IF($A$8=0,B8))) -> 0 | C16: =IF($A$8<0,C11*-$A$8+C8,IF($A$8>0,C11*-$A$8+C8,IF($A$8=0,C8))) -> -1 | D16: =IF($A$8<0,D11*-$A$8+D8,IF($A$8>0,D11*-$A$8+D8,IF($A$8=0,D8))) -> 0 | E16: =IF($A$8<0,E11*-$A$8+E8,IF($A$8>0,E11*-$A$8+E8,IF($A$8=0,E8))) -> -1 | F16: =IF($A$8<0,F11*-$A$8+F8,IF($A$8>0,F11*-$A$8+F8,IF($A$8=0,F8))) -> 4 | G16: =IF($A$8<0,G11*-$A$8+G8,IF($A$8>0,G11*-$A$8+G8,IF($A$8=0,G8))) -> 1.6666667 | I16: =A32 -> 0 | J16: =B32 -> 0 | K16: =C32 -> 0 | L16: =IF($D$32<0,L14*-$D$32+D32,IF($D$32>0,L14*-$D$32+D32,IF($D$32=0,D32))) -> 0 | M16: =IF($D$32<0,M14*-$D$32+E32,IF($D$32>0,M14*-$D$32+E32,IF($D$32=0,E32))) -> -1.1111111 | N16: =IF($D$32<0,N14*-$D$32+F32,IF($D$32>0,N14*-$D$32+F32,IF($D$32=0,F32))) -> 3.7222222 | O16: =IF($D$32<0,O14*-$D$32+G32,IF($D$32>0,O14*-$D$32+G32,IF($D$32=0,G32))) -> 2.4814815
A18: a | B18: b | C18: c | D18: d | E18: e | F18: f | G18: Igualdad | I18: a | J18: b | K18: c | L18: d | M18: e | N18: f | O18: Igualdad
A19: =A11 -> 1 | B19: =B11 -> -1.5 | C19: =C11 -> 0 | D19: =D11 -> 0 | E19: =E11 -> 0 | F19: =F11 -> 0 | G19: =G11 -> -0.83333333 | I19: =I11 -> 1 | J19: =J11 -> -1.5 | K19: =K11 -> 0 | L19: =L11 -> 0 | M19: =M11 -> 0 | N19: =N11 -> 0 | O19: =O11 -> -0.83333333
A20: =A12 -> 0 | B20: =IF($B$12=1,B12,B12/$B$12) -> 1 | C20: =IF($B$12=1,C12,C12/$B$12) -> -0.4 | D20: =IF($B$12=1,D12,D12/$B$12) -> 0 | E20: =IF($B$12=1,E12,E12/$B$12) -> -0.4 | F20: =IF($B$12=1,F12,F12/$B$12) -> 0 | G20: =IF($B$12=1,G12,G12/$B$12) -> -0.066666667 | I20: =I12 -> 0 | J20: =J12 -> 1 | K20: =K12 -> -0.4 | L20: =L12 -> 0 | M20: =M12 -> -0.4 | N20: =N12 -> 0 | O20: =O12 -> -0.066666667
A21: =A13 -> 0 | B21: =IF($B$13<0,B20*-$B$13+B13,IF($B$13>0,B20*-$B$13+B13,IF($B$13=0,B13))) -> 0 | C21: =IF($B$13<0,C20*-$B$13+C13,IF($B$13>0,C20*-$B$13+C13,IF($B$13=0,C13))) -> 3.6 | D21: =IF($B$13<0,D20*-$B$13+D13,IF($B$13>0,D20*-$B$13+D13,IF($B$13=0,D13))) -> 0 | E21: =IF($B$13<0,E20*-$B$13+E13,IF($B$13>0,E20*-$B$13+E13,IF($B$13=0,E13))) -> -0.4 | F21: =IF($B$13<0,F20*-$B$13+F13,IF($B$13>0,F20*-$B$13+F13,IF($B$13=0,F13))) -> -1 | G21: =IF($B$13<0,G20*-$B$13+G13,IF($B$13>0,G20*-$B$13+G13,IF($B$13=0,G13))) -> 2.9333333 | I21: =I13 -> 0 | J21: =J13 -> 0 | K21: =K13 -> 1 | L21: =L13 -> 0 | M21: =M13 -> -0.11111111 | N21: =N13 -> -0.27777778 | O21: =O13 -> 0.81481481
A22: =A14 -> 0 | B22: =IF($B$14<0,B20*-$B$14+B14,IF($B$14>0,B20*-$B$14+B14,IF($B$14=0,B14))) -> 0 | C22: =IF($B$14<0,C20*-$B$14+C14,IF($B$14>0,C20*-$B$14+C14,IF($B$14=0,C14))) -> 0 | D22: =IF($B$14<0,D20*-$B$14+D14,IF($B$14>0,D20*-$B$14+D14,IF($B$14=0,D14))) -> 2 | E22: =IF($B$14<0,E20*-$B$14+E14,IF($B$14>0,E20*-$B$14+E14,IF($B$14=0,E14))) -> -3 | F22: =IF($B$14<0,F20*-$B$14+F14,IF($B$14>0,F20*-$B$14+F14,IF($B$14=0,F14))) -> 0 | G22: =IF($B$14<0,G20*-$B$14+G14,IF($B$14>0,G20*-$B$14+G14,IF($B$14=0,G14))) -> -1.3333333 | I22: =I14 -> 0 | J22: =J14 -> 0 | K22: =K14 -> 0 | L22: =L14 -> 1 | M22: =M14 -> -1.5 | N22: =N14 -> 0 | O22: =O14 -> -0.66666667
A23: =A15 -> 0 | B23: =IF($B$15<0,B20*-$B$15+B15,IF($B$15>0,B20*-$B$15+B15,IF($B$15=0,B15))) -> 0 | C23: =IF($B$15<0,C20*-$B$15+C15,IF($B$15>0,C20*-$B$15+C15,IF($B$15=0,C15))) -> -0.4 | D23: =IF($B$15<0,D20*-$B$15+D15,IF($B$15>0,D20*-$B$15+D15,IF($B$15=0,D15))) -> -1 | E23: =IF($B$15<0,E20*-$B$15+E15,IF($B$15>0,E20*-$B$15+E15,IF($B$15=0,E15))) -> 3.6 | F23: =IF($B$15<0,F20*-$B$15+F15,IF($B$15>0,F20*-$B$15+F15,IF($B$15=0,F15))) -> -1 | G23: =IF($B$15<0,G20*-$B$15+G15,IF($B$15>0,G20*-$B$15+G15,IF($B$15=0,G15))) -> -0.4 | I23: =I15 -> 0 | J23: =J15 -> 0 | K23: =K15 -> 0 | L23: =L15 -> 0 | M23: =IF($M$15=1,M15,M15/$M$15) -> 1 | N23: =IF($M$15=1,N15,N15/$M$15) -> -0.54054054 | O23: =IF($M$15=1,O15,O15/$M$15) -> -0.36036036
A24: =A16 -> 0 | B24: =IF($B$16<0,B20*-$B$16+B16,IF($B$16>0,B20*-$B$16+B16,IF($B$16=0,B16))) -> 0 | C24: =IF($B$16<0,C20*-$B$16+C16,IF($B$16>0,C20*-$B$16+C16,IF($B$16=0,C16))) -> -1 | D24: =IF($B$16<0,D20*-$B$16+D16,IF($B$16>0,D20*-$B$16+D16,IF($B$16=0,D16))) -> 0 | E24: =IF($B$16<0,E20*-$B$16+E16,IF($B$16>0,E20*-$B$16+E16,IF($B$16=0,E16))) -> -1 | F24: =IF($B$16<0,F20*-$B$16+F16,IF($B$16>0,F20*-$B$16+F16,IF($B$16=0,F16))) -> 4 | G24: =IF($B$16<0,G20*-$B$16+G16,IF($B$16>0,G20*-$B$16+G16,IF($B$16=0,G16))) -> 1.6666667 | I24: =I16 -> 0 | J24: =J16 -> 0 | K24: =K16 -> 0 | L24: =L16 -> 0 | M24: =IF($M$16<0,M23*-$M$16+M16,IF($M$16>0,M23*-$M$16+M16,IF($M$16=0,M16))) -> 0 | N24: =IF($M$16<0,N23*-$M$16+N16,IF($M$16>0,N23*-$M$16+N16,IF($M$16=0,N16))) -> 3.1216216 | O24: =IF($M$16<0,O23*-$M$16+O16,IF($M$16>0,O23*-$M$16+O16,IF($M$16=0,O16))) -> 2.0810811
A26: a | B26: b | C26: c | D26: d | E26: e | F26: f | G26: Igualdad | I26: a | J26: b | K26: c | L26: d | M26: e | N26: f | O26: Igualdad
A27: =A19 -> 1 | B27: =B19 -> -1.5 | C27: =C19 -> 0 | D27: =D19 -> 0 | E27: =E19 -> 0 | F27: =F19 -> 0 | G27: =G19 -> -0.83333333 | I27: =I19 -> 1 | J27: =J19 -> -1.5 | K27: =K19 -> 0 | L27: =L19 -> 0 | M27: =M19 -> 0 | N27: =N19 -> 0 | O27: =O19 -> -0.83333333
A28: =A20 -> 0 | B28: =B20 -> 1 | C28: =C20 -> -0.4 | D28: =D20 -> 0 | E28: =E20 -> -0.4 | F28: =F20 -> 0 | G28: =G20 -> -0.066666667 | I28: =I20 -> 0 | J28: =J20 -> 1 | K28: =K20 -> -0.4 | L28: =L20 -> 0 | M28: =M20 -> -0.4 | N28: =N20 -> 0 | O28: =O20 -> -0.066666667
A29: =A21 -> 0 | B29: =B21 -> 0 | C29: =IF($C$21=1,C21,C21/$C$21) -> 1 | D29: =IF($C$21=1,D21,D21/$C$21) -> 0 | E29: =IF($C$21=1,E21,E21/$C$21) -> -0.11111111 | F29: =IF($C$21=1,F21,F21/$C$21) -> -0.27777778 | G29: =IF($C$21=1,G21,G21/$C$21) -> 0.81481481 | I29: =I21 -> 0 | J29: =J21 -> 0 | K29: =K21 -> 1 | L29: =L21 -> 0 | M29: =M21 -> -0.11111111 | N29: =N21 -> -0.27777778 | O29: =O21 -> 0.81481481
A30: =A22 -> 0 | B30: =B22 -> 0 | C30: =IF($C$22<0,C29*-$C$22+C22,IF($C$22>0,C29*-$C$22+C22,IF($C$22=0,C22))) -> 0 | D30: =IF($C$22<0,D29*-$C$22+D22,IF($C$22>0,D29*-$C$22+D22,IF($C$22=0,D22))) -> 2 | E30: =IF($C$22<0,E29*-$C$22+E22,IF($C$22>0,E29*-$C$22+E22,IF($C$22=0,E22))) -> -3 | F30: =IF($C$22<0,F29*-$C$22+F22,IF($C$22>0,F29*-$C$22+F22,IF($C$22=0,F22))) -> 0 | G30: =IF($C$22<0,G29*-$C$22+G22,IF($C$22>0,G29*-$C$22+G22,IF($C$22=0,G22))) -> -1.3333333 | I30: =I22 -> 0 | J30: =J22 -> 0 | K30: =K22 -> 0 | L30: =L22 -> 1 | M30: =M22 -> -1.5 | N30: =N22 -> 0 | O30: =O22 -> -0.66666667
A31: =A23 -> 0 | B31: =B23 -> 0 | C31: =IF($C$23<0,C29*-$C$23+C23,IF($C$23>0,C29*-$C$23+C23,IF($C$23=0,C23))) -> 0 | D31: =IF($C$23<0,D29*-$C$23+D23,IF($C$23>0,D29*-$C$23+D23,IF($C$23=0,D23))) -> -1 | E31: =IF($C$23<0,E29*-$C$23+E23,IF($C$23>0,E29*-$C$23+E23,IF($C$23=0,E23))) -> 3.5555556 | F31: =IF($C$23<0,F29*-$C$23+F23,IF($C$23>0,F29*-$C$23+F23,IF($C$23=0,F23))) -> -1.1111111 | G31: =IF($C$23<0,G29*-$C$23+G23,IF($C$23>0,G29*-$C$23+G23,IF($C$23=0,G23))) -> -0.074074074 | I31: =I23 -> 0 | J31: =J23 -> 0 | K31: =K23 -> 0 | L31: =L23 -> 0 | M31: =M23 -> 1 | N31: =N23 -> -0.54054054 | O31: =O23 -> -0.36036036
A32: =A24 -> 0 | B32: =B24 -> 0 | C32: =IF($C$24<0,C29*-$C$24+C24,IF($C$24>0,C29*-$C$24+C24,IF($C$24=0,C24))) -> 0 | D32: =IF($C$24<0,D29*-$C$24+D24,IF($C$24>0,D29*-$C$24+D24,IF($C$24=0,D24))) -> 0 | E32: =IF($C$24<0,E29*-$C$24+E24,IF($C$24>0,E29*-$C$24+E24,IF($C$24=0,E24))) -> -1.1111111 | F32: =IF($C$24<0,F29*-$C$24+F24,IF($C$24>0,F29*-$C$24+F24,IF($C$24=0,F24))) -> 3.7222222 | G32: =IF($C$24<0,G29*-$C$24+G24,IF($C$24>0,G29*-$C$24+G24,IF($C$24=0,G24))) -> 2.4814815 | I32: =I24 -> 0 | J32: =J24 -> 0 | K32: =K24 -> 0 | L32: =L24 -> 0 | M32: =M24 -> 0 | N32: =IF($N$24=1,N24,N24/$N$24) -> 1 | O32: =IF($N$24=1,O24,O24/$N$24) -> 0.66666667
B35: a | C35: b | D35: c | E35: d | F35: e | G35: f | H35: Igualdad | J35: Resultado
B36: =I27 -> 1 | C36: =J27 -> -1.5 | D36: =K27 -> 0 | E36: =L27 -> 0 | F36: =M27 -> 0 | G36: =N27 -> 0 | H36: =O27 -> -0.83333333 | J36: a | K36: =H36+(-G36*K41)+(-F36*K40)+(-E36*K39)+(-D36*K38)+(-C36*K37) -> -0.33333333
C37: =J28 -> 1 | D37: =K28 -> -0.4 | E37: =L28 -> 0 | F37: =M28 -> -0.4 | G37: =N28 -> 0 | H37: =O28 -> -0.066666667 | J37: b | K37: =H37+(-G37*K41)+(-F37*K40)+(-E37*K39)+(-D37*K38) -> 0.33333333
D38: =K29 -> 1 | E38: =L29 -> 0 | F38: =M29 -> -0.11111111 | G38: =N29 -> -0.27777778 | H38: =O29 -> 0.81481481 | J38: c | K38: =H38+(-G38*K41)+(-F38*K40)+(-E38*K39) -> 1
E39: =L30 -> 1 | F39: =M30 -> -1.5 | G39: =N30 -> 0 | H39: =O30 -> -0.66666667 | J39: d | K39: =H39+(-G39*K41)+(-F39*K40) -> -0.66666667
F40: =M31 -> 1 | G40: =N31 -> -0.54054054 | H40: =O31 -> -0.36036036 | J40: e | K40: =H40+(-G40*K41) -> 0
G41: =N32 -> 1 | H41: =O32 -> 0.66666667 | J41: f | K41: =H41 -> 0.66666667

Sheet Eliminación de Gauss-Jordan
A1: a | B1: b | C1: c | D1: d | E1: e | F1: f | G1: Igualdad | I1: a | J1: b | K1: c | L1: d | M1: e | N1: f | O1: Igualdad | Q1: Respuesta
A2: {='Sistema de Ecuaciones'!A3:G8} -> 2 | B2: -3 | C2: 0 | D2: 0 | E2: 0 | F2: 0 | G2: -1.6666667 | I2: =A58 -> 1 | J2: =B58 -> -1.5 | K2: =C58 -> 0 | L2: =D58 -> 0 | M2: =E58 -> 0 | N2: =IF(F58=0,F58,F58+(F58*(-$N$7))) -> 0 | O2: =IF(F58=0,G58,G58+(F58*(-$O$7))) -> -0.83333333 | Q2: a | R2: =O34 -> -0.33333333
A3: -1 | B3: 4 | C3: -1 | D3: 0 | E3: -1 | F3: 0 | G3: 0.66666667 | I3: =A59 -> 0 | J3: =B59 -> 1 | K3: =C59 -> -0.4 | L3: =D59 -> 0 | M3: =E59 -> -0.4 | N3: =IF(F59=0,F59,F59+(F59*(-$N$7))) -> 0 | O3: =IF(F59=0,G59,G59+(F59*(-$O$7))) -> -0.066666667 | Q3: b | R3: =O35 -> 0.33333333
A4: 0 | B4: -1 | C4: 4 | D4: 0 | E4: 0 | F4: -1 | G4: 3 | I4: =A60 -> 0 | J4: =B60 -> 0 | K4: =C60 -> 1 | L4: =D60 -> 0 | M4: =E60 -> -0.11111111 | N4: =IF(F60=0,F60,F60+(F60*(-$N$7))) -> 0 | O4: =IF(F60=0,G60,G60+(F60*(-$O$7))) -> 1 | Q4: c | R4: =O36 -> 1
A5: 0 | B5: 0 | C5: 0 | D5: 2 | E5: -3 | F5: 0 | G5: -1.3333333 | I5: =A61 -> 0 | J5: =B61 -> 0 | K5: =C61 -> 0 | L5: =D61 -> 1 | M5: =E61 -> -1.5 | N5: =IF(F61=0,F61,F61+(F61*(-$N$7))) -> 0 | O5: =IF(F61=0,G61,G61+(F61*(-$O$7))) -> -0.66666667 | Q5: d | R5: =O37 -> -0.66666667
A6: 0 | B6: -1 | C6: 0 | D6: -1 | E6: 4 | F6: -1 | G6: -0.33333333 | I6: =A62 -> 0 | J6: =B62 -> 0 | K6: =C62 -> 0 | L6: =D62 -> 0 | M6: =E62 -> 1 | N6: =IF(F62=0,F62,F62+(F62*(-$N$7))) -> 0 | O6: =IF(F62=0,G62,G62+(F62*(-$O$7))) -> 0 | Q6: e | R6: =O38 -> 0
A7: 0 | B7: 0 | C7: -1 | D7: 0 | E7: -1 | F7: 4 | G7: 1.6666667 | I7: =A63 -> 0 | J7: =B63 -> 0 | K7: =C63 -> 0 | L7: =D63 -> 0 | M7: =E63 -> 0 | N7: =F63 -> 1 | O7: =G63 -> 0.66666667 | Q7: f | R7: =O39 -> 0.66666667
A9: a | B9: b | C9: c | D9: d | E9: e | F9: f | G9: Igualdad | I9: a | J9: b | K9: c | L9: d | M9: e | N9: f | O9: Igualdad
A10: =IF($A$2=1,A2,A2*(1/$A$2)) -> 1 | B10: =IF($A$2=1,B2,B2*(1/$A$2)) -> -1.5 | C10: =IF($A$2=1,C2,C2*(1/$A$2)) -> 0 | D10: =IF($A$2=1,D2,D2*(1/$A$2)) -> 0 | E10: =IF($A$2=1,E2,E2*(1/$A$2)) -> 0 | F10: =IF($A$2=1,F2,F2*(1/$A$2)) -> 0 | G10: =IF($A$2=1,G2,G2*(1/$A$2)) -> -0.83333333 | I10: =I2 -> 1 | J10: =J2 -> -1.5 | K10: =K2 -> 0 | L10: =L2 -> 0 | M10: =IF(E58=0,E58,E58+(E58*(-$M$6))) -> 0 | N10: =N2 -> 0 | O10: =IF(E58=0,O2,O2+(E58*(-$O$6))) -> -0.83333333
A11: =IF(A3=0,A3,A3+($A$10*(-A3))) -> 0 | B11: =IF(A3=0,B3,B3+($B$10*(-A3))) -> 2.5 | C11: =IF(A3=0,C3,C3+($C$10*(-A3))) -> -1 | D11: =IF(A3=0,D3,D3+($D$10*(-A3))) -> 0 | E11: =IF(A3=0,E3,E3+($E$10*(-A3))) -> -1 | F11: =IF(A3=0,F3,F3+($F$10*(-A3))) -> 0 | G11: =IF(A3=0,G3,G3+($G$10*(-A3))) -> -0.16666667 | I11: =I3 -> 0 | J11: =J3 -> 1 | K11: =K3 -> -0.4 | L11: =L3 -> 0 | M11: =IF(E59=0,E59,E59+(E59*(-$M$6))) -> 0 | N11: =N3 -> 0 | O11: =IF(E59=0,O3,O3+(E59*(-$O$6))) -> -0.066666667
A12: =IF(A4=0,A4,A4+($A$10*(-A4))) -> 0 | B12: =IF(A4=0,B4,B4+($B$10*(-A4))) -> -1 | C12: =IF(A4=0,C4,C4+($C$10*(-A4))) -> 4 | D12: =IF(A4=0,D4,D4+($D$10*(-A4))) -> 0 | E12: =IF(A4=0,E4,E4+($E$10*(-A4))) -> 0 | F12: =IF(A4=0,F4,F4+($F$10*(-A4))) -> -1 | G12: =IF(A4=0,G4,G4+($G$10*(-A4))) -> 3 | I12: =I4 -> 0 | J12: =J4 -> 0 | K12: =K4 -> 1 | L12: =L4 -> 0 | M12: =IF(E60=0,E60,E60+(E60*(-$M$6))) -> 0 | N12: =N4 -> 0 | O12: =IF(E60=0,O4,O4+(E60*(-$O$6))) -> 1
A13: =IF(A5=0,A5,A5+($A$10*(-A5))) -> 0 | B13: =IF(A5=0,B5,B5+($B$10*(-A5))) -> 0 | C13: =IF(A5=0,C5,C5+($C$10*(-A5))) -> 0 | D13: =IF(A5=0,D5,D5+($D$10*(-A5))) -> 2 | E13: =IF(A5=0,E5,E5+($E$10*(-A5))) -> -3 | F13: =IF(A5=0,F5,F5+($F$10*(-A5))) -> 0 | G13: =IF(A5=0,G5,G5+($G$10*(-A5))) -> -1.3333333 | I13: =I5 -> 0 | J13: =J5 -> 0 | K13: =K5 -> 0 | L13: =L5 -> 1 | M13: =IF(E61=0,E61,E61+(E61*(-$M$6))) -> 0 | N13: =N5 -> 0 | O13: =IF(E61=0,O5,O5+(E61*(-$O$6))) -> -0.66666667
A14: =IF(A6=0,A6,A6+($A$10*(-A6))) -> 0 | B14: =IF(A6=0,B6,B6+($B$10*(-A6))) -> -1 | C14: =IF(A6=0,C6,C6+($C$10*(-A6))) -> 0 | D14: =IF(A6=0,D6,D6+($D$10*(-A6))) -> -1 | E14: =IF(A6=0,E6,E6+($E$10*(-A6))) -> 4 | F14: =IF(A6=0,F6,F6+($F$10*(-A6))) -> -1 | G14: =IF(A6=0,G6,G6+($G$10*(-A6))) -> -0.33333333 | I14: =I6 -> 0 | J14: =J6 -> 0 | K14: =K6 -> 0 | L14: =L6 -> 0 | M14: =M6 -> 1 | N14: =N6 -> 0 | O14: =O6 -> 0
A15: =IF(A7=0,A7,A7+($A$10*(-A7))) -> 0 | B15: =IF(A7=0,B7,B7+($B$10*(-A7))) -> 0 | C15: =IF(A7=0,C7,C7+($C$10*(-A7))) -> -1 | D15: =IF(A7=0,D7,D7+($D$10*(-A7))) -> 0 | E15: =IF(A7=0,E7,E7+($E$10*(-A7))) -> -1 | F15: =IF(A7=0,F7,F7+($F$10*(-A7))) -> 4 | G15: =IF(A7=0,G7,G7+($G$10*(-A7))) -> 1.6666667 | I15: =I7 -> 0 | J15: =J7 -> 0 | K15: =K7 -> 0 | L15: =L7 -> 0 | M15: =M7 -> 0 | N15: =N7 -> 1 | O15: =O7 -> 0.66666667
A17: a | B17: b | C17: c | D17: d | E17: e | F17: f | G17: Igualdad | I17: a | J17: b | K17: c | L17: d | M17: e | N17: f | O17: Igualdad
A18: =A10 -> 1 | B18: =B10 -> -1.5 | C18: =C10 -> 0 | D18: =D10 -> 0 | E18: =E10 -> 0 | F18: =F10 -> 0 | G18: =G10 -> -0.83333333 | I18: =I10 -> 1 | J18: =J10 -> -1.5 | K18: =K10 -> 0 | L18: =IF(L10=0,L10,L10+(L10*(-$L$21))) -> 0 | M18: =M10 -> 0 | N18: =N10 -> 0 | O18: =IF(L10=0,O10,L10+(L10*(-$O$21))) -> -0.83333333
A19: =A11 -> 0 | B19: =IF($B$11=1,B11,B11*(1/B11)) -> 1 | C19: =IF($B$11=1,C11,C11*(1/$B$11)) -> -0.4 | D19: =IF($B$11=1,D11,D11*(1/$B$11)) -> 0 | E19: =IF($B$11=1,E11,E11*(1/$B$11)) -> -0.4 | F19: =IF($B$11=1,F11,F11*(1/$B$11)) -> 0 | G19: =IF($B$11=1,G11,G11*(1/$B$11)) -> -0.066666667 | I19: =I11 -> 0 | J19: =J11 -> 1 | K19: =K11 -> -0.4 | L19: =IF(L11=0,L11,L11+(L11*(-$L$21))) -> 0 | M19: =M11 -> 0 | N19: =N11 -> 0 | O19: =IF(L11=0,O11,L11+(L11*(-$O$21))) -> -0.066666667
A20: =A12 -> 0 | B20: =IF(B12=0,B12,B12+($B$19*(-B12))) -> 0 | C20: =IF(B12=0,C12,C12+($C$19*(-B12))) -> 3.6 | D20: =IF(B12=0,D12,D12+($D$19*(-B12))) -> 0 | E20: =IF(B12=0,E12,E12+($E$19*(-B12))) -> -0.4 | F20: =IF(B12=0,F12,F12+($F$19*(-B12))) -> -1 | G20: =IF(B12=0,G12,G12+($G$19*(-B12))) -> 2.9333333 | I20: =I12 -> 0 | J20: =J12 -> 0 | K20: =K12 -> 1 | L20: =IF(L12=0,L12,L12+(L12*(-$L$21))) -> 0 | M20: =M12 -> 0 | N20: =N12 -> 0 | O20: =IF(L12=0,O12,O12+(L12*(-$O$21))) -> 1
A21: =A13 -> 0 | B21: =IF(B13=0,B13,B13+($B$19*(-B13))) -> 0 | C21: =IF(B13=0,C13,C13+($C$19*(-B13))) -> 0 | D21: =IF(B13=0,D13,D13+($D$19*(-B13))) -> 2 | E21: =IF(B13=0,E13,E13+($E$19*(-B13))) -> -3 | F21: =IF(B13=0,F13,F13+($F$19*(-B13))) -> 0 | G21: =IF(B13=0,G13,G13+($G$19*(-B13))) -> -1.3333333 | I21: =I13 -> 0 | J21: =J13 -> 0 | K21: =K13 -> 0 | L21: =L13 -> 1 | M21: =M13 -> 0 | N21: =N13 -> 0 | O21: =O13 -> -0.66666667
A22: =A14 -> 0 | B22: =IF(B14=0,B14,B14+($B$19*(-B14))) -> 0 | C22: =IF(B14=0,C14,C14+($C$19*(-B14))) -> -0.4 | D22: =IF(B14=0,D14,D14+($D$19*(-B14))) -> -1 | E22: =IF(B14=0,E14,E14+($E$19*(-B14))) -> 3.6 | F22: =IF(B14=0,F14,F14+($F$19*(-B14))) -> -1 | G22: =IF(B14=0,G14,G14+($G$19*(-B14))) -> -0.4 | I22: =I14 -> 0 | J22: =J14 -> 0 | K22: =K14 -> 0 | L22: =L14 -> 0 | M22: =M14 -> 1 | N22: =N14 -> 0 | O22: =O14 -> 0
A23: =A15 -> 0 | B23: =IF(B15=0,B15,B15+($B$19*(-B15))) -> 0 | C23: =IF(B15=0,C15,C15+($C$19*(-B15))) -> -1 | D23: =IF(B15=0,D15,D15+($D$19*(-B15))) -> 0 | E23: =IF(B15=0,E15,E15+($E$19*(-B15))) -> -1 | F23: =IF(B15=0,F15,F15+($F$19*(-B15))) -> 4 | G23: =IF(B15=0,G15,G15+($G$19*(-B15))) -> 1.6666667 | I23: =I15 -> 0 | J23: =J15 -> 0 | K23: =K15 -> 0 | L23: =L15 -> 0 | M23: =M15 -> 0 | N23: =N15 -> 1 | O23: =O15 -> 0.66666667
A25: a | B25: b | C25: c | D25: d | E25: e | F25: f | G25: Igualdad | I25: a | J25: b | K25: c | L25: d | M25: e | N25: f | O25: Igualdad
A26: =A18 -> 1 | B26: =B18 -> -1.5 | C26: =C18 -> 0 | D26: =D18 -> 0 | E26: =E18 -> 0 | F26: =F18 -> 0 | G26: =G18 -> -0.83333333 | I26: =I18 -> 1 | J26: =J18 -> -1.5 | K26: =IF(K18=0,K18,K18+(K18*(-$K$20))) -> 0 | L26: =L18 -> 0 | M26: =M18 -> 0 | N26: =N18 -> 0 | O26: =IF(K18=0,O18,O18+(K18*(-O19))) -> -0.83333333
A27: =A19 -> 0 | B27: =B19 -> 1 | C27: =C19 -> -0.4 | D27: =D19 -> 0 | E27: =E19 -> -0.4 | F27: =F19 -> 0 | G27: =G19 -> -0.066666667 | I27: =I19 -> 0 | J27: =J19 -> 1 | K27: =IF(K19=0,K19,K19+(K19*(-$K$20))) -> 0 | L27: =L19 -> 0 | M27: =M19 -> 0 | N27: =N19 -> 0 | O27: =IF(K19=0,O19,O19+(K19*(-$O$28))) -> 0.33333333
A28: =A20 -> 0 | B28: =IF(B20=0,B20,B20+($B$19*(-B20))) -> 0 | C28: =IF(B20=0,C20,C20+($C$19*(-B20))) -> 3.6 | D28: =IF(B20=0,D20,D20+($D$19*(-B20))) -> 0 | E28: =IF(B20=0,E20,E20+($E$19*(-B20))) -> -0.4 | F28: =IF(B20=0,F20,F20+($F$19*(-B20))) -> -1 | G28: =IF(B20=0,G20,G20+($G$19*(-B20))) -> 2.9333333 | I28: =I20 -> 0 | J28: =J20 -> 0 | K28: =K20 -> 1 | L28: =L20 -> 0 | M28: =M20 -> 0 | N28: =N20 -> 0 | O28: =O20 -> 1
A29: =A21 -> 0 | B29: =IF(B21=0,B21,B21+($B$19*(-B21))) -> 0 | C29: =IF(B21=0,C21,C21+($C$19*(-B21))) -> 0 | D29: =IF(B21=0,D21,D21+($D$19*(-B21))) -> 2 | E29: =IF(B21=0,E21,E21+($E$19*(-B21))) -> -3 | F29: =IF(B21=0,F21,F21+($F$19*(-B21))) -> 0 | G29: =IF(B21=0,G21,G21+($G$19*(-B21))) -> -1.3333333 | I29: =I21 -> 0 | J29: =J21 -> 0 | K29: =K21 -> 0 | L29: =L21 -> 1 | M29: =M21 -> 0 | N29: =N21 -> 0 | O29: =O21 -> -0.66666667
A30: =A22 -> 0 | B30: =IF(B22=0,B22,B22+($B$19*(-B22))) -> 0 | C30: =IF(B22=0,C22,C22+($C$19*(-B22))) -> -0.4 | D30: =IF(B22=0,D22,D22+($D$19*(-B22))) -> -1 | E30: =IF(B22=0,E22,E22+($E$19*(-B22))) -> 3.6 | F30: =IF(B22=0,F22,F22+($F$19*(-B22))) -> -1 | G30: =IF(B22=0,G22,G22+($G$19*(-B22))) -> -0.4 | I30: =I22 -> 0 | J30: =J22 -> 0 | K30: =K22 -> 0 | L30: =L22 -> 0 | M30: =M22 -> 1 | N30: =N22 -> 0 | O30: =O22 -> 0
A31: =A23 -> 0 | B31: =IF(B23=0,B23,B23+($B$19*(-B23))) -> 0 | C31: =IF(B23=0,C23,C23+($C$19*(-B23))) -> -1 | D31: =IF(B23=0,D23,D23+($D$19*(-B23))) -> 0 | E31: =IF(B23=0,E23,E23+($E$19*(-B23))) -> -1 | F31: =IF(B23=0,F23,F23+($F$19*(-B23))) -> 4 | G31: =IF(B23=0,G23,G23+($G$19*(-B23))) -> 1.6666667 | I31: =I23 -> 0 | J31: =J23 -> 0 | K31: =K23 -> 0 | L31: =L23 -> 0 | M31: =M23 -> 0 | N31: =N23 -> 1 | O31: =O23 -> 0.66666667
A33: a | B33: b | C33: c | D33: d | E33: e | F33: f | G33: Igualdad | I33: a | J33: b | K33: c | L33: d | M33: e | N33: f | O33: Igualdad
A34: =A26 -> 1 | B34: =B26 -> -1.5 | C34: =C26 -> 0 | D34: =D26 -> 0 | E34: =E26 -> 0 | F34: =F26 -> 0 | G34: =G26 -> -0.83333333 | I34: =I26 -> 1 | J34: =IF(J26=0,J26,J26+(J26*(-J35))) -> 0 | K34: =K26 -> 0 | L34: =L26 -> 0 | M34: =M26 -> 0 | N34: =N26 -> 0 | O34: =IF(J26=0,O26,O26+(O35*(-J26))) -> -0.33333333
A35: =A27 -> 0 | B35: =B27 -> 1 | C35: =C27 -> -0.4 | D35: =D27 -> 0 | E35: =E27 -> -0.4 | F35: =F27 -> 0 | G35: =G27 -> -0.066666667 | I35: =I27 -> 0 | J35: =J27 -> 1 | K35: =K27 -> 0 | L35: =L27 -> 0 | M35: =M27 -> 0 | N35: =N27 -> 0 | O35: =O27 -> 0.33333333
A36: =A28 -> 0 | B36: =B28 -> 0 | C36: =IF($C$28=1,C28,C28*(1/$C$28)) -> 1 | D36: =IF($C$28=1,D28,D28*(1/$C$28)) -> 0 | E36: =IF($C$28=1,E28,E28*(1/$C$28)) -> -0.11111111 | F36: =IF($C$28=1,F28,F28*(1/$C$28)) -> -0.27777778 | G36: =IF($C$28=1,G28,G28*(1/$C$28)) -> 0.81481481 | I36: =I28 -> 0 | J36: =J28 -> 0 | K36: =K28 -> 1 | L36: =L28 -> 0 | M36: =M28 -> 0 | N36: =N28 -> 0 | O36: =O28 -> 1
A37: =A29 -> 0 | B37: =B29 -> 0 | C37: =IF(C29=0,C29,C29+($C$36*(-C29))) -> 0 | D37: =IF(D29=0,D29,D29+($D$36*(-C29))) -> 2 | E37: =IF(E29=0,E29,E29+($E$36*(-C29))) -> -3 | F37: =IF(F29=0,F29,F29+($F$36*(-C29))) -> 0 | G37: =IF(G29=0,G29,G29+($G$36*(-C29))) -> -1.3333333 | I37: =I29 -> 0 | J37: =J29 -> 0 | K37: =K29 -> 0 | L37: =L29 -> 1 | M37: =M29 -> 0 | N37: =N29 -> 0 | O37: =O29 -> -0.66666667
A38: =A30 -> 0 | B38: =B30 -> 0 | C38: =IF(C30=0,C30,C30+($C$36*(-C30))) -> 0 | D38: =IF(D30=0,D30,D30+($D$36*(-C30))) -> -1 | E38: =IF(E30=0,E30,E30+($E$36*(-C30))) -> 3.5555556 | F38: =IF(F30=0,F30,F30+($F$36*(-C30))) -> -1.1111111 | G38: =IF(G30=0,G30,G30+($G$36*(-C30))) -> -0.074074074 | I38: =I30 -> 0 | J38: =J30 -> 0 | K38: =K30 -> 0 | L38: =L30 -> 0 | M38: =M30 -> 1 | N38: =N30 -> 0 | O38: =O30 -> 0
A39: =A31 -> 0 | B39: =B31 -> 0 | C39: =IF(C31=0,C31,C31+($C$36*(-C31))) -> 0 | D39: =IF(D31=0,D31,D31+($D$36*(-C31))) -> 0 | E39: =IF(E31=0,E31,E31+($E$36*(-C31))) -> -1.1111111 | F39: =IF(F31=0,F31,F31+($F$36*(-C31))) -> 3.7222222 | G39: =IF(G31=0,G31,G31+($G$36*(-C31))) -> 2.4814815 | I39: =I31 -> 0 | J39: =J31 -> 0 | K39: =K31 -> 0 | L39: =L31 -> 0 | M39: =M31 -> 0 | N39: =N31 -> 1 | O39: =O31 -> 0.66666667
A41: a | B41: b | C41: c | D41: d | E41: e | F41: f | G41: Igualdad
A42: =A34 -> 1 | B42: =B34 -> -1.5 | C42: =C34 -> 0 | D42: =D34 -> 0 | E42: =E34 -> 0 | F42: =F34 -> 0 | G42: =G34 -> -0.83333333
A43: =A35 -> 0 | B43: =B35 -> 1 | C43: =C35 -> -0.4 | D43: =D35 -> 0 | E43: =E35 -> -0.4 | F43: =F35 -> 0 | G43: =G35 -> -0.066666667
A44: =A36 -> 0 | B44: =B36 -> 0 | C44: =C36 -> 1 | D44: =D36 -> 0 | E44: =E36 -> -0.11111111 | F44: =F36 -> -0.27777778 | G44: =G36 -> 0.81481481
A45: =A37 -> 0 | B45: =B37 -> 0 | C45: =C37 -> 0 | D45: =IF($D$37=1,D37,D37*(1/$D$37)) -> 1 | E45: =IF($D$37=1,E37,E37*(1/$D$37)) -> -1.5 | F45: =IF($D$37=1,F37,F37*(1/$D$37)) -> 0 | G45: =IF($D$37=1,G37,G37*(1/$D$37)) -> -0.66666667
...

Sheet Inversión de Matrices
A2: a | B2: b | C2: c | D2: d | E2: e | F2: f | G2: Igualdad
A3: ='Sistema de Ecuaciones'!A3 -> 2 | B3: ='Sistema de Ecuaciones'!B3 -> -3 | C3: ='Sistema de Ecuaciones'!C3 -> 0 | D3: ='Sistema de Ecuaciones'!D3 -> 0 | E3: ='Sistema de Ecuaciones'!E3 -> 0 | F3: ='Sistema de Ecuaciones'!F3 -> 0 | G3: ='Sistema de Ecuaciones'!G3 -> -1.6666667
A4: ='Sistema de Ecuaciones'!A4 -> -1 | B4: ='Sistema de Ecuaciones'!B4 -> 4 | C4: ='Sistema de Ecuaciones'!C4 -> -1 | D4: ='Sistema de Ecuaciones'!D4 -> 0 | E4: ='Sistema de Ecuaciones'!E4 -> -1 | F4: ='Sistema de Ecuaciones'!F4 -> 0 | G4: ='Sistema de Ecuaciones'!G4 -> 0.66666667
A5: ='Sistema de Ecuaciones'!A5 -> 0 | B5: ='Sistema de Ecuaciones'!B5 -> -1 | C5: ='Sistema de Ecuaciones'!C5 -> 4 | D5: ='Sistema de Ecuaciones'!D5 -> 0 | E5: ='Sistema de Ecuaciones'!E5 -> 0 | F5: ='Sistema de Ecuaciones'!F5 -> -1 | G5: ='Sistema de Ecuaciones'!G5 -> 3
A6: ='Sistema de Ecuaciones'!A6 -> 0 | B6: ='Sistema de Ecuaciones'!B6 -> 0 | C6: ='Sistema de Ecuaciones'!C6 -> 0 | D6: ='Sistema de Ecuaciones'!D6 -> 2 | E6: ='Sistema de Ecuaciones'!E6 -> -3 | F6: ='Sistema de Ecuaciones'!F6 -> 0 | G6: ='Sistema de Ecuaciones'!G6 -> -1.3333333
A7: ='Sistema de Ecuaciones'!A7 -> 0 | B7: ='Sistema de Ecuaciones'!B7 -> -1 | C7: ='Sistema de Ecuaciones'!C7 -> 0 | D7: ='Sistema de Ecuaciones'!D7 -> -1 | E7: ='Sistema de Ecuaciones'!E7 -> 4 | F7: ='Sistema de Ecuaciones'!F7 -> -1 | G7: ='Sistema de Ecuaciones'!G7 -> -0.33333333
A8: ='Sistema de Ecuaciones'!A8 -> 0 | B8: ='Sistema de Ecuaciones'!B8 -> 0 | C8: ='Sistema de Ecuaciones'!C8 -> -1 | D8: ='Sistema de Ecuaciones'!D8 -> 0 | E8: ='Sistema de Ecuaciones'!E8 -> -1 | F8: ='Sistema de Ecuaciones'!F8 -> 4 | G8: ='Sistema de Ecuaciones'!G8 -> 1.6666667
A10: Matriz Inversa | H10: Resultado
A11: {=MINVERSE(A3:F8)} -> 0.93506494 | B11: 0.87012987 | C11: 0.25974026 | D11: 0.20779221 | E11: 0.41558442 | F11: 0.16883117 | H11: a | I11: {=MMULT(A11:F16,G3:G8)} -> -0.33333333
A12: 0.29004329 | B12: 0.58008658 | C12: 0.17316017 | D12: 0.13852814 | E12: 0.27705628 | F12: 0.11255411 | H12: b | I12: 0.33333333
A13: 0.086580087 | B13: 0.17316017 | C13: 0.32034632 | D13: 0.056277056 | E13: 0.11255411 | F13: 0.10822511 | H13: c | I13: 1
A14: 0.20779221 | B14: 0.41558442 | C14: 0.16883117 | D14: 0.93506494 | E14: 0.87012987 | F14: 0.25974026 | H14: d | I14: -0.66666667
A15: 0.13852814 | B15: 0.27705628 | C15: 0.11255411 | D15: 0.29004329 | E15: 0.58008658 | F15: 0.17316017 | H15: e | I15: 5.5511151e-17
A16: 0.056277056 | B16: 0.11255411 | C16: 0.10822511 | D16: 0.086580087 | E16: 0.17316017 | F16: 0.32034632 | H16: f | I16: 0.66666667

Sheet Regla de Cramer
A1: DET (A) | H1: DET(A) | J1: Respuesta
A2: {='Sistema de Ecuaciones'!A3:F8} -> 2 | B2: -3 | C2: 0 | D2: 0 | E2: 0 | F2: 0 | H2: {=MDETERM(A2:F7)} -> 231 | J2: a | K2: =H10/$H$2 -> -0.33333333
A3: -1 | B3: 4 | C3: -1 | D3: 0 | E3: -1 | F3: 0 | J3: b | K3: =H18/$H$2 -> 0.33333333
A4: 0 | B4: -1 | C4: 4 | D4: 0 | E4: 0 | F4: -1 | J4: c | K4: =H26/$H$2 -> 1
A5: 0 | B5: 0 | C5: 0 | D5: 2 | E5: -3 | F5: 0 | J5: d | K5: =H34/$H$2 -> -0.66666667
A6: 0 | B6: -1 | C6: 0 | D6: -1 | E6: 4 | F6: -1 | J6: e | K6: =H42/$H$2 -> 8.5870064e-17
A7: 0 | B7: 0 | C7: -1 | D7: 0 | E7: -1 | F7: 4 | J7: f | K7: =H50/$H$2 -> 0.66666667
A9: DET (A1) | H9: DET(A1)
A10: {='Sistema de Ecuaciones'!$G$3:$G$8} -> -1.6666667 | B10: =B2 -> -3 | C10: =C2 -> 0 | D10: =D2 -> 0 | E10: =E2 -> 0 | F10: =F2 -> 0 | H10: {=MDETERM(A10:F15)} -> -77
A11: 0.66666667 | B11: =B3 -> 4 | C11: =C3 -> -1 | D11: =D3 -> 0 | E11: =E3 -> -1 | F11: =F3 -> 0
A12: 3 | B12: =B4 -> -1 | C12: =C4 -> 4 | D12: =D4 -> 0 | E12: =E4 -> 0 | F12: =F4 -> -1
A13: -1.3333333 | B13: =B5 -> 0 | C13: =C5 -> 0 | D13: =D5 -> 2 | E13: =E5 -> -3 | F13: =F5 -> 0
A14: -0.33333333 | B14: =B6 -> -1 | C14: =C6 -> 0 | D14: =D6 -> -1 | E14: =E6 -> 4 | F14: =F6 -> -1
A15: 1.6666667 | B15: =B7 -> 0 | C15: =C7 -> -1 | D15: =D7 -> 0 | E15: =E7 -> -1 | F15: =F7 -> 4
A17: DET (A2) | H17: DET(A2)
A18: =A2 -> 2 | B18: {='Sistema de Ecuaciones'!$G$3:$G$8} -> -1.6666667 | C18: =C2 -> 0 | D18: =D2 -> 0 | E18: =E2 -> 0 | F18: =F2 -> 0 | H18: {=MDETERM(A18:F23)} -> 77
A19: =A3 -> -1 | B19: 0.66666667 | C19: =C3 -> -1 | D19: =D3 -> 0 | E19: =E3 -> -1 | F19: =F3 -> 0
A20: =A4 -> 0 | B20: 3 | C20: =C4 -> 4 | D20: =D4 -> 0 | E20: =E4 -> 0 | F20: =F4 -> -1
A21: =A5 -> 0 | B21: -1.3333333 | C21: =C5 -> 0 | D21: =D5 -> 2 | E21: =E5 -> -3 | F21: =F5 -> 0
A22: =A6 -> 0 | B22: -0.33333333 | C22: =C6 -> 0 | D22: =D6 -> -1 | E22: =E6 -> 4 | F22: =F6 -> -1
A23: =A7 -> 0 | B23: 1.6666667 | C23: =C7 -> -1 | D23: =D7 -> 0 | E23: =E7 -> -1 | F23: =F7 -> 4
A25: DET (A3) | H25: DET(A3)
A26: =A2 -> 2 | B26: =B2 -> -3 | C26: {='Sistema de Ecuaciones'!$G$3:$G$8} -> -1.6666667 | D26: =D2 -> 0 | E26: =E2 -> 0 | F26: =F2 -> 0 | H26: {=MDETERM(A26:F31)} -> 231
A27: =A3 -> -1 | B27: =B3 -> 4 | C27: 0.66666667 | D27: =D3 -> 0 | E27: =E3 -> -1 | F27: =F3 -> 0
A28: =A4 -> 0 | B28: =B4 -> -1 | C28: 3 | D28: =D4 -> 0 | E28: =E4 -> 0 | F28: =F4 -> -1
A29: =A5 -> 0 | B29: =B5 -> 0 | C29: -1.3333333 | D29: =D5 -> 2 | E29: =E5 -> -3 | F29: =F5 -> 0
A30: =A6 -> 0 | B30: =B6 -> -1 | C30: -0.33333333 | D30: =D6 -> -1 | E30: =E6 -> 4 | F30: =F6 -> -1
A31: =A7 -> 0 | B31: =B7 -> 0 | C31: 1.6666667 | D31: =D7 -> 0 | E31: =E7 -> -1 | F31: =F7 -> 4
A33: DET (A4) | H33: DET(A4)
A34: =A2 -> 2 | B34: =B10 -> -3 | C34: =C10 -> 0 | D34: {='Sistema de Ecuaciones'!$G$3:$G$8} -> -1.6666667 | E34: =E10 -> 0 | F34: =F10 -> 0 | H34: {=MDETERM(A34:F39)} -> -154
A35: =A3 -> -1 | B35: =B11 -> 4 | C35: =C11 -> -1 | D35: 0.66666667 | E35: =E11 -> -1 | F35: =F11 -> 0
A36: =A4 -> 0 | B36: =B12 -> -1 | C36: =C12 -> 4 | D36: 3 | E36: =E12 -> 0 | F36: =F12 -> -1
A37: =A5 -> 0 | B37: =B13 -> 0 | C37: =C13 -> 0 | D37: -1.3333333 | E37: =E13 -> -3 | F37: =F13 -> 0
A38: =A6 -> 0 | B38: =B14 -> -1 | C38: =C14 -> 0 | D38: -0.33333333 | E38: =E14 -> 4 | F38: =F14 -> -1
A39: =A7 -> 0 | B39: =B15 -> 0 | C39: =C15 -> -1 | D39: 1.6666667 | E39: =E15 -> -1 | F39: =F15 -> 4
A41: DET (A5) | H41: DET(A5)
A42: =A2 -> 2 | B42: =B2 -> -3 | C42: =C2 -> 0 | D42: =D2 -> 0 | E42: {='Sistema de Ecuaciones'!$G$3:$G$8} -> -1.6666667 | F42: =F18 -> 0 | H42: {=MDETERM(A42:F47)} -> 1.9835985e-14
A43: =A3 -> -1 | B43: =B3 -> 4 | C43: =C3 -> -1 | D43: =D3 -> 0 | E43: 0.66666667 | F43: =F19 -> 0
A44: =A4 -> 0 | B44: =B4 -> -1 | C44: =C4 -> 4 | D44: =D4 -> 0 | E44: 3 | F44: =F20 -> -1
A45: =A5 -> 0 | B45: =B5 -> 0 | C45: =C5 -> 0 | D45: =D5 -> 2 | E45: -1.3333333 | F45: =F21 -> 0
...

Sheet Método Montante
A2: a | B2: b | C2: c | D2: d | E2: e | F2: f | G2: Igualdad | I2: Pivote
A3: ='Sistema de Ecuaciones'!A3 -> 2 | B3: ='Sistema de Ecuaciones'!B3 -> -3 | C3: ='Sistema de Ecuaciones'!C3 -> 0 | D3: ='Sistema de Ecuaciones'!D3 -> 0 | E3: ='Sistema de Ecuaciones'!E3 -> 0 | F3: ='Sistema de Ecuaciones'!F3 -> 0 | G3: ='Sistema de Ecuaciones'!G3 -> -1.6666667 | I3: 1
A4: ='Sistema de Ecuaciones'!A4 -> -1 | B4: ='Sistema de Ecuaciones'!B4 -> 4 | C4: ='Sistema de Ecuaciones'!C4 -> -1 | D4: ='Sistema de Ecuaciones'!D4 -> 0 | E4: ='Sistema de Ecuaciones'!E4 -> -1 | F4: ='Sistema de Ecuaciones'!F4 -> 0 | G4: ='Sistema de Ecuaciones'!G4 -> 0.66666667
A5: ='Sistema de Ecuaciones'!A5 -> 0 | B5: ='Sistema de Ecuaciones'!B5 -> -1 | C5: ='Sistema de Ecuaciones'!C5 -> 4 | D5: ='Sistema de Ecuaciones'!D5 -> 0 | E5: ='Sistema de Ecuaciones'!E5 -> 0 | F5: ='Sistema de Ecuaciones'!F5 -> -1 | G5: ='Sistema de Ecuaciones'!G5 -> 3
A6: ='Sistema de Ecuaciones'!A6 -> 0 | B6: ='Sistema de Ecuaciones'!B6 -> 0 | C6: ='Sistema de Ecuaciones'!C6 -> 0 | D6: ='Sistema de Ecuaciones'!D6 -> 2 | E6: ='Sistema de Ecuaciones'!E6 -> -3 | F6: ='Sistema de Ecuaciones'!F6 -> 0 | G6: ='Sistema de Ecuaciones'!G6 -> -1.3333333
A7: ='Sistema de Ecuaciones'!A7 -> 0 | B7: ='Sistema de Ecuaciones'!B7 -> -1 | C7: ='Sistema de Ecuaciones'!C7 -> 0 | D7: ='Sistema de Ecuaciones'!D7 -> -1 | E7: ='Sistema de Ecuaciones'!E7 -> 4 | F7: ='Sistema de Ecuaciones'!F7 -> -1 | G7: ='Sistema de Ecuaciones'!G7 -> -0.33333333
A8: ='Sistema de Ecuaciones'!A8 -> 0 | B8: ='Sistema de Ecuaciones'!B8 -> 0 | C8: ='Sistema de Ecuaciones'!C8 -> -1 | D8: ='Sistema de Ecuaciones'!D8 -> 0 | E8: ='Sistema de Ecuaciones'!E8 -> -1 | F8: ='Sistema de Ecuaciones'!F8 -> 4 | G8: ='Sistema de Ecuaciones'!G8 -> 1.6666667
A10: a | B10: b | C10: c | D10: d | E10: e | F10: f | G10: Igualdad | I10: Pivote
A11: =($B$12*A3-$A$12*B11)/$I$11 -> 5 | B11: =B3 -> -3 | C11: =C3 -> 0 | D11: =D3 -> 0 | E11: =E3 -> 0 | F11: =F3 -> 0 | G11: =G3 -> -1.6666667 | I11: =A3 -> 2
A12: 0 | B12: =($A$3*B4-$A$4*B3)/$I$3 -> 5 | C12: =($A$3*C4-$A$4*C3)/$I$3 -> -2 | D12: =($A$3*D4-$A$4*D3)/$I$3 -> 0 | E12: =($A$3*E4-$A$4*E3)/$I$3 -> -2 | F12: =($A$3*F4-$A$4*F3)/$I$3 -> 0 | G12: =($A$3*G4-$A$4*G3)/$I$3 -> -0.33333333
A13: 0 | B13: =($A$3*B5-$A$5*B3)/$I$3 -> -2 | C13: =($A$3*C5-$A$5*C3)/$I$3 -> 8 | D13: =($A$3*D5-$A$5*D3)/$I$3 -> 0 | E13: =($A$3*E5-$A$5*E3)/$I$3 -> 0 | F13: =($A$3*F5-$A$5*F3)/$I$3 -> -2 | G13: =($A$3*G5-$A$5*G3)/$I$3 -> 6
A14: 0 | B14: =($A$3*B6-$A$6*B3)/$I$3 -> 0 | C14: =($A$3*C6-$A$6*C3)/$I$3 -> 0 | D14: =($A$3*D6-$A$6*D3)/$I$3 -> 4 | E14: =($A$3*E6-$A$6*E3)/$I$3 -> -6 | F14: =($A$3*F6-$A$6*F3)/$I$3 -> 0 | G14: =($A$3*G6-$A$6*G3)/$I$3 -> -2.6666667
A15: 0 | B15: =($A$3*B7-$A$7*B3)/$I$3 -> -2 | C15: =($A$3*C7-$A$7*C3)/$I$3 -> 0 | D15: =($A$3*D7-$A$7*D3)/$I$3 -> -2 | E15: =($A$3*E7-$A$7*E3)/$I$3 -> 8 | F15: =($A$3*F7-$A$7*F3)/$I$3 -> -2 | G15: =($A$3*G7-$A$7*G3)/$I$3 -> -0.66666667
A16: 0 | B16: =($A$3*B8-$A$8*B3)/$I$3 -> 0 | C16: =($A$3*C8-$A$8*C3)/$I$3 -> -2 | D16: =($A$3*D8-$A$8*D3)/$I$3 -> 0 | E16: =($A$3*E8-$A$8*E3)/$I$3 -> -2 | F16: =($A$3*F8-$A$8*F3)/$I$3 -> 8 | G16: =($A$3*G8-$A$8*G3)/$I$3 -> 3.3333333
A18: a | B18: b | C18: c | D18: d | E18: e | F18: f | G18: Igualdad | I18: Pivote
A19: =($A$11*B20-$A$20*B19)/$I$19 -> 18 | B19: 0 | C19: =($B$12*C11-$B$11*C12)/$I$11 -> -3 | D19: =($B$12*D11-$B$11*D12)/$I$11 -> 0 | E19: =($B$12*E11-$B$11*E12)/$I$11 -> -3 | F19: =($B$12*F11-$B$11*F12)/$I$11 -> 0 | G19: =($B$12*G11-$B$11*G12)/$I$11 -> -4.6666667 | I19: =A11 -> 5
A20: =A12 -> 0 | B20: =($B$12*C21-$B$21*C20)/$I$19 -> 18 | C20: =C12 -> -2 | D20: =D12 -> 0 | E20: =E12 -> -2 | F20: =F12 -> 0 | G20: =G12 -> -0.33333333
A21: =A13 -> 0 | B21: 0 | C21: =($B$12*C13-$B$13*C12)/$I$11 -> 18 | D21: =($B$12*D13-$B$13*D12)/$I$11 -> 0 | E21: =($B$12*E13-$B$13*E12)/$I$11 -> -2 | F21: =($B$12*F13-$B$13*F12)/$I$11 -> -5 | G21: =($B$12*G13-$B$13*G12)/$I$11 -> 14.666667
A22: =A14 -> 0 | B22: 0 | C22: =($B$12*C14-$B$14*C12)/$I$11 -> 0 | D22: =($B$12*D14-$B$14*D12)/$I$11 -> 10 | E22: =($B$12*E14-$B$14*E12)/$I$11 -> -15 | F22: =($B$12*F14-$B$14*F12)/$I$11 -> 0 | G22: =($B$12*G14-$B$14*G12)/$I$11 -> -6.6666667
A23: =A15 -> 0 | B23: 0 | C23: =($B$12*C15-$B$15*C12)/$I$11 -> -2 | D23: =($B$12*D15-$B$15*D12)/$I$11 -> -5 | E23: =($B$12*E15-$B$15*E12)/$I$11 -> 18 | F23: =($B$12*F15-$B$15*F12)/$I$11 -> -5 | G23: =($B$12*G15-$B$15*G12)/$I$11 -> -2
A24: =A16 -> 0 | B24: 0 | C24: =($B$12*C16-$B$16*C12)/$I$11 -> -5 | D24: =($B$12*D16-$B$16*D12)/$I$11 -> 0 | E24: =($B$12*E16-$B$16*E12)/$I$11 -> -5 | F24: =($B$12*F16-$B$16*F12)/$I$11 -> 20 | G24: =($B$12*G16-$B$16*G12)/$I$11 -> 8.3333333
A26: a | B26: b | C26: c | D26: d | E26: e | F26: f | G26: Igualdad | I26: Pivote
A27: =($C$21*B28-$C$30*B27)/$I$27 -> 36 | B27: =B19 -> 0 | C27: 0 | D27: =($C$21*D19-$C$19*D21)/$I$19 -> 0 | E27: =($C$21*E19-$C$19*E21)/$I$19 -> -12 | F27: =($C$21*F19-$C$19*F21)/$I$19 -> -3 | G27: =($C$21*G19-$C$19*G21)/$I$19 -> -8 | I27: =A19 -> 18
A28: =A20 -> 0 | B28: =($C$21*C29-$C$30*C28)/$I$27 -> 36 | C28: 0 | D28: =($C$21*D20-$C$20*D21)/$I$19 -> 0 | E28: =($C$21*E20-$C$20*E21)/$I$19 -> -8 | F28: =($C$21*F20-$C$20*F21)/$I$19 -> -2 | G28: =($C$21*G20-$C$20*G21)/$I$19 -> 4.6666667
A29: =A21 -> 0 | B29: =B21 -> 0 | C29: =($C$21*D30-$C$30*D29)/$I$27 -> 36 | D29: =D21 -> 0 | E29: =E21 -> -2 | F29: =F21 -> -5 | G29: =G21 -> 14.666667
A30: =A22 -> 0 | B30: =B22 -> 0 | C30: 0 | D30: =($C$21*D22-$C$22*D21)/$I$19 -> 36 | E30: =($C$21*E22-$C$22*E21)/$I$19 -> -54 | F30: =($C$21*F22-$C$22*F21)/$I$19 -> 0 | G30: =($C$21*G22-$C$22*G21)/$I$19 -> -24
A31: =A23 -> 0 | B31: =B23 -> 0 | C31: 0 | D31: =($C$21*D23-$C$23*D21)/$I$19 -> -18 | E31: =($C$21*E23-$C$23*E21)/$I$19 -> 64 | F31: =($C$21*F23-$C$23*F21)/$I$19 -> -20 | G31: =($C$21*G23-$C$23*G21)/$I$19 -> -1.3333333
A32: =A24 -> 0 | B32: =B24 -> 0 | C32: 0 | D32: =($C$21*D24-$C$24*D21)/$I$19 -> 0 | E32: =($C$21*E24-$C$24*E21)/$I$19 -> -20 | F32: =($C$21*F24-$C$24*F21)/$I$19 -> 67 | G32: =($C$21*G24-$C$24*G21)/$I$19 -> 44.666667
A34: a | B34: b | C34: c | D34: d | E34: e | F34: f | G34: Igualdad | I34: Pivote
A35: =($D$30*B36-$D$39*B35)/$I$35 -> 74 | B35: =B27 -> 0 | C35: =C27 -> 0 | D35: =D27 -> 0 | E35: =($D$30*E27-$D$27*E30)/$I$27 -> -24 | F35: =($D$30*F27-$D$27*F30)/$I$27 -> -6 | G35: =($D$30*G27-$D$27*G30)/$I$27 -> -16 | I35: =A27 -> 36
A36: =A28 -> 0 | B36: =($D$30*C37-$D$39*C36)/$I$35 -> 74 | C36: =C28 -> 0 | D36: =D28 -> 0 | E36: =($D$30*E28-$D$28*E30)/$I$27 -> -16 | F36: =($D$30*F28-$D$28*F30)/$I$27 -> -4 | G36: =($D$30*G28-$D$28*G30)/$I$27 -> 9.3333333
A37: =A29 -> 0 | B37: =B29 -> 0 | C37: =($D$30*D38-$D$39*D37)/$I$35 -> 74 | D37: =D29 -> 0 | E37: =($D$30*E29-$D$29*E30)/$I$27 -> -4 | F37: =($D$30*F29-$D$29*F30)/$I$27 -> -10 | G37: =($D$30*G29-$D$29*G30)/$I$27 -> 29.333333
A38: =A30 -> 0 | B38: =B30 -> 0 | C38: =C30 -> 0 | D38: =($D$30*E39-$D$39*E38)/$I$35 -> 74 | E38: =E30 -> -54 | F38: =F30 -> 0 | G38: =G30 -> -24
A39: =A31 -> 0 | B39: =B31 -> 0 | C39: =C31 -> 0 | D39: 0 | E39: =($D$30*E31-$D$31*E30)/$I$27 -> 74 | F39: =($D$30*F31-$D$31*F30)/$I$27 -> -40 | G39: =($D$30*G31-$D$31*G30)/$I$27 -> -26.666667
A40: =A32 -> 0 | B40: =B32 -> 0 | C40: =C32 -> 0 | D40: =D32 -> 0 | E40: =($D$30*E32-$D$32*E30)/$I$27 -> -40 | F40: =($D$30*F32-$D$32*F30)/$I$27 -> 134 | G40: =($D$30*G32-$D$32*G30)/$I$27 -> 89.333333
A42: a | B42: b | C42: c | D42: d | E42: e | F42: f | G42: Igualdad | I42: Pivote
A43: =($E$39*B44-$E$48*B43)/$I$43 -> 231 | B43: =B35 -> 0 | C43: =C35 -> 0 | D43: =D35 -> 0 | E43: 0 | F43: =($E$39*F35-$E$35*F39)/$I$35 -> -39 | G43: =($E$39*G35-$E$35*G39)/$I$35 -> -50.666667 | I43: =A35 -> 74
A44: =A36 -> 0 | B44: =($E$39*C45-$E$48*C44)/$I$43 -> 231 | C44: =C36 -> 0 | D44: =D36 -> 0 | E44: 0 | F44: =($E$39*F36-$E$36*F39)/$I$35 -> -26 | G44: =($E$39*G36-$E$36*G39)/$I$35 -> 7.3333333
A45: =A37 -> 0 | B45: =B37 -> 0 | C45: =($E$39*D46-$E$48*D45)/$I$43 -> 231 | D45: =D37 -> 0 | E45: 0 | F45: =($E$39*F37-$E$37*F39)/$I$35 -> -25 | G45: =($E$39*G37-$E$37*G39)/$I$35 -> 57.333333
A46: =A38 -> 0 | B46: =B38 -> 0 | C46: =C38 -> 0 | D46: =($E$39*E47-$E$48*E46)/$I$43 -> 231 | E46: 0 | F46: =($E$39*F38-$E$38*F39)/$I$35 -> -60 | G46: =($E$39*G38-$E$38*G39)/$I$35 -> -89.333333
...

Sheet Gauss-Jacobi
A1: a | B1: b | C1: c | D1: d | E1: e | F1: f | G1: igualdad
A2: {='Sistema de Ecuaciones'!A3:G8} -> 2 | B2: -3 | C2: 0 | D2: 0 | E2: 0 | F2: 0 | G2: -1.6666667 | J2: ncs | K2: 7
A3: -1 | B3: 4 | C3: -1 | D3: 0 | E3: -1 | F3: 0 | G3: 0.66666667 | J3: E | K3: =0.5*10^(2-K2) -> 5e-06
A4: 0 | B4: -1 | C4: 4 | D4: 0 | E4: 0 | F4: -1 | G4: 3
A5: 0 | B5: 0 | C5: 0 | D5: 2 | E5: -3 | F5: 0 | G5: -1.3333333
A6: 0 | B6: -1 | C6: 0 | D6: -1 | E6: 4 | F6: -1 | G6: -0.33333333
A7: 0 | B7: 0 | C7: -1 | D7: 0 | E7: -1 | F7: 4 | G7: 1.6666667
A9: k | B9: a | C9: b | D9: c | E9: d | F9: e | G9: f | H9: cck
A10: 0 | B10: 0 | C10: 0 | D10: 0 | E10: 0 | F10: 0 | G10: 0 | H10: 100
A11: 1 | B11: =($G$2-($B$2*C10+$C$2*D10+$D$2*E10+$E$2*F10+$F$2*G10))/($A$2) -> -0.83333333 | C11: =($G$3-($A$3*B10+$C$3*D10+$D$3*E10+$E$3*F10+$F$3*G10))/($B$3) -> 0.16666667 | D11: =($G$4-($A$4*B10+$B$4*C10+$D$4*E10+$E$4*F10+$F$4*G10))/($C$4) -> 0.75 | E11: =($G$5-($A$5*B10+$B$5*C10+$C$5*D10+$E$5*F10+$F$5*G10))/($D$5) -> -0.66666667 | F11: =($G$6-($A$6*B10+$B$6*C10+$C$6*D10+$D$6*E10+$F$6*G10))/($E$6) -> -0.083333333 | G11: =($G$7-($A$7*B10+$B$7*C10+$C$7*D10+$D$7*E10+$E$7*F10))/($F$7) -> 0.41666667 | H11: {=(MAX(ABS((B11:G11)-(B10:G10)))/MAX(ABS(B11:G11))*100)} -> 100

Sheet Gauss-Seidel
A2: a | B2: b | C2: c | D2: d | E2: e | F2: f | G2: Igualdad | I2: Ncs | J2: 7
A3: ='Sistema de Ecuaciones'!A3 -> 2 | B3: ='Sistema de Ecuaciones'!B3 -> -3 | C3: ='Sistema de Ecuaciones'!C3 -> 0 | D3: ='Sistema de Ecuaciones'!D3 -> 0 | E3: ='Sistema de Ecuaciones'!E3 -> 0 | F3: ='Sistema de Ecuaciones'!F3 -> 0 | G3: ='Sistema de Ecuaciones'!G3 -> -1.6666667 | I3: E | J3: =0.5*10^(2-J2) -> 5e-06
A4: ='Sistema de Ecuaciones'!A4 -> -1 | B4: ='Sistema de Ecuaciones'!B4 -> 4 | C4: ='Sistema de Ecuaciones'!C4 -> -1 | D4: ='Sistema de Ecuaciones'!D4 -> 0 | E4: ='Sistema de Ecuaciones'!E4 -> -1 | F4: ='Sistema de Ecuaciones'!F4 -> 0 | G4: ='Sistema de Ecuaciones'!G4 -> 0.66666667
A5: ='Sistema de Ecuaciones'!A5 -> 0 | B5: ='Sistema de Ecuaciones'!B5 -> -1 | C5: ='Sistema de Ecuaciones'!C5 -> 4 | D5: ='Sistema de Ecuaciones'!D5 -> 0 | E5: ='Sistema de Ecuaciones'!E5 -> 0 | F5: ='Sistema de Ecuaciones'!F5 -> -1 | G5: ='Sistema de Ecuaciones'!G5 -> 3
A6: ='Sistema de Ecuaciones'!A6 -> 0 | B6: ='Sistema de Ecuaciones'!B6 -> 0 | C6: ='Sistema de Ecuaciones'!C6 -> 0 | D6: ='Sistema de Ecuaciones'!D6 -> 2 | E6: ='Sistema de Ecuaciones'!E6 -> -3 | F6: ='Sistema de Ecuaciones'!F6 -> 0 | G6: ='Sistema de Ecuaciones'!G6 -> -1.3333333
A7: ='Sistema de Ecuaciones'!A7 -> 0 | B7: ='Sistema de Ecuaciones'!B7 -> -1 | C7: ='Sistema de Ecuaciones'!C7 -> 0 | D7: ='Sistema de Ecuaciones'!D7 -> -1 | E7: ='Sistema de Ecuaciones'!E7 -> 4 | F7: ='Sistema de Ecuaciones'!F7 -> -1 | G7: ='Sistema de Ecuaciones'!G7 -> -0.33333333
A8: ='Sistema de Ecuaciones'!A8 -> 0 | B8: ='Sistema de Ecuaciones'!B8 -> 0 | C8: ='Sistema de Ecuaciones'!C8 -> -1 | D8: ='Sistema de Ecuaciones'!D8 -> 0 | E8: ='Sistema de Ecuaciones'!E8 -> -1 | F8: ='Sistema de Ecuaciones'!F8 -> 4 | G8: ='Sistema de Ecuaciones'!G8 -> 1.6666667
A10: k | B10: a | C10: b | D10: c | E10: d | F10: e | G10: f | H10: cck
A11: 0 | B11: =G3/A3 -> -0.83333333 | C11: =G4/B4 -> 0.16666667 | D11: =G5/C5 -> 0.75 | E11: =G6/D6 -> -0.66666667 | F11: =G7/E7 -> -0.083333333 | G11: =G8/F8 -> 0.41666667 | H11: 100
A12: 1 | B12: =($G$3-($B$3*C11+$C$3*D11+$D$3*E11+$E$3*F11+$F$3*G11))/($A$3) -> -0.58333333 | C12: =($G$4-($A$4*B12+$C$4*D11+$D$4*E11+$E$4*F11+$F$4*G11))/($B$4) -> 0.1875 | D12: =($G$5-($A$5*B12+$B$5*C12+$D$5*E11+$E$5*F11+$F$5*G11))/($C$5) -> 0.90104167 | E12: =($G$6-($A$6*B12+$B$6*C12+$C$6*D12+$E$6*F11+$F$6*G11))/($D$6) -> -0.79166667 | F12: =($G$7-($A$7*B12+$B$7*C12+$C$7*D12+$D$7*E12+$F$7*G11))/($E$7) -> -0.13020833 | G12: =($G$8-($A$8*B12+$B$8*C12+$C$8*D12+$D$8*E12+$E$8*F12))/($F$8) -> 0.609375 | H12: {=(MAX(ABS(B12:G12-B11:G11))/MAX(ABS(B12:G12))*100)} -> 27.745665
